<?xml version="1.0" ?>
<!-- =================================================================================== -->
<!-- |    This document was autogenerated by xacro from /home/administrator/jackal_ws/src/jackal/jackal_description/urdf/jackal.urdf.xacro | -->
<!-- |    EDITING THIS FILE BY HAND IS NOT RECOMMENDED                                 | -->
<!-- =================================================================================== -->
<robot name="jackal" xmlns:body="http://playerstage.sourceforge.net/gazebo/xmlschema/#body" xmlns:controller="http://playerstage.sourceforge.net/gazebo/xmlschema/#controller" xmlns:gazebo="http://playerstage.sourceforge.net/gazebo/xmlschema/#gz" xmlns:geom="http://playerstage.sourceforge.net/gazebo/xmlschema/#geom" xmlns:interface="http://playerstage.sourceforge.net/gazebo/xmlschema/#interface" xmlns:joint="http://playerstage.sourceforge.net/gazebo/xmlschema/#joint" xmlns:model="http://playerstage.sourceforge.net/gazebo/xmlschema/#model" xmlns:physics="http://playerstage.sourceforge.net/gazebo/xmlschema/#physics" xmlns:renderable="http://playerstage.sourceforge.net/gazebo/xmlschema/#renderable" xmlns:rendering="http://playerstage.sourceforge.net/gazebo/xmlschema/#rendering" xmlns:sensor="http://playerstage.sourceforge.net/gazebo/xmlschema/#sensor" xmlns:xi="http://www.w3.org/2001/XInclude">
    <material name="dark_grey">
        <color rgba="0.2 0.2 0.2 1.0" />
    </material>
    <material name="light_grey">
        <color rgba="0.4 0.4 0.4 1.0" />
    </material>
    <material name="yellow">
        <color rgba="0.8 0.8 0.0 1.0" />
    </material>
    <material name="black">
        <color rgba="0.15 0.15 0.15 1.0" />
    </material>
    <link name="front_left_wheel_link">
        <visual>
            <origin rpy="1.5707963267948966 0 0" xyz="0 0 0" />
            <geometry>
                <mesh filename="package://jackal_description/meshes/jackal-wheel.stl" />
            </geometry>
            <material name="black" />
        </visual>
        <collision>
            <origin rpy="1.5707963267948966 0 0" xyz="0 0 0" />
            <geometry>
                <cylinder length="0.04" radius="0.098" />
            </geometry>
        </collision>
        <inertial>
            <origin rpy="0 0 0" xyz="0 0 0" />
            <mass value="0.477" />
            <inertia ixx="0.0013" ixy="0" ixz="0" iyy="0.0024" iyz="0" izz="0.0013" />
        </inertial>
    </link>
    <gazebo reference="front_left_wheel_link">
        <material>Gazebo/DarkGrey</material>
        <selfCollide>false</selfCollide>
        <mu1 value="0.5" />
        <mu2 value="0.5" />
        <kp value="10000000.0" />
        <kd value="1" />
        <fdir1 value="1 0 0" />
        <plugin name="gazebo_ros_control">
            <robotNamespace>/</robotNamespace>
        </plugin>
    </gazebo>
    <joint name="front_left_wheel" type="continuous">
        <parent link="chassis_link" />
        <child link="front_left_wheel_link" />
        <origin rpy="0 0 0" xyz="0.131 0.187795 0.0345" />
        <axis xyz="0 1 0" />
    </joint>
    <!-- In reality, Jackal has only two motors, one per side. However, it's more
         straightforward for Gazebo to simulate as if there's an actuator per wheel. -->
    <transmission name="front_left_wheel_trans">
        <type>transmission_interface/SimpleTransmission</type>
        <joint name="front_left_wheel">
            <hardwareInterface>hardware_interface/VelocityJointInterface</hardwareInterface>
        </joint>
        <actuator name="front_left_actuator">
            <mechanicalReduction>1</mechanicalReduction>
            <hardwareInterface>hardware_interface/EffortJointInterface</hardwareInterface>
        </actuator>
    </transmission>
    <link name="front_right_wheel_link">
        <visual>
            <origin rpy="1.5707963267948966 0 0" xyz="0 0 0" />
            <geometry>
                <mesh filename="package://jackal_description/meshes/jackal-wheel.stl" />
            </geometry>
            <material name="black" />
        </visual>
        <collision>
            <origin rpy="1.5707963267948966 0 0" xyz="0 0 0" />
            <geometry>
                <cylinder length="0.04" radius="0.098" />
            </geometry>
        </collision>
        <inertial>
            <origin rpy="0 0 0" xyz="0 0 0" />
            <mass value="0.477" />
            <inertia ixx="0.0013" ixy="0" ixz="0" iyy="0.0024" iyz="0" izz="0.0013" />
        </inertial>
    </link>
    <gazebo reference="front_right_wheel_link">
        <material>Gazebo/DarkGrey</material>
        <selfCollide>false</selfCollide>
        <mu1 value="0.5" />
        <mu2 value="0.5" />
        <kp value="10000000.0" />
        <kd value="1" />
        <fdir1 value="1 0 0" />
    </gazebo>
    <joint name="front_right_wheel" type="continuous">
        <parent link="chassis_link" />
        <child link="front_right_wheel_link" />
        <origin rpy="0 0 0" xyz="0.131 -0.187795 0.0345" />
        <axis xyz="0 1 0" />
    </joint>
    <!-- In reality, Jackal has only two motors, one per side. However, it's more
         straightforward for Gazebo to simulate as if there's an actuator per wheel. -->
    <transmission name="front_right_wheel_trans">
        <type>transmission_interface/SimpleTransmission</type>
        <joint name="front_right_wheel">
            <hardwareInterface>hardware_interface/VelocityJointInterface</hardwareInterface>
        </joint>
        <actuator name="front_right_actuator">
            <mechanicalReduction>1</mechanicalReduction>
            <hardwareInterface>hardware_interface/EffortJointInterface</hardwareInterface>
        </actuator>
    </transmission>
    <link name="rear_left_wheel_link">
        <visual>
            <origin rpy="1.5707963267948966 0 0" xyz="0 0 0" />
            <geometry>
                <mesh filename="package://jackal_description/meshes/jackal-wheel.stl" />
            </geometry>
            <material name="black" />
        </visual>
        <collision>
            <origin rpy="1.5707963267948966 0 0" xyz="0 0 0" />
            <geometry>
                <cylinder length="0.04" radius="0.098" />
            </geometry>
        </collision>
        <inertial>
            <origin rpy="0 0 0" xyz="0 0 0" />
            <mass value="0.477" />
            <inertia ixx="0.0013" ixy="0" ixz="0" iyy="0.0024" iyz="0" izz="0.0013" />
        </inertial>
    </link>
    <gazebo reference="rear_left_wheel_link">
        <material>Gazebo/DarkGrey</material>
        <selfCollide>false</selfCollide>
        <mu1 value="0.5" />
        <mu2 value="0.5" />
        <kp value="10000000.0" />
        <kd value="1" />
        <fdir1 value="1 0 0" />
    </gazebo>
    <joint name="rear_left_wheel" type="continuous">
        <parent link="chassis_link" />
        <child link="rear_left_wheel_link" />
        <origin rpy="0 0 0" xyz="-0.131 0.187795 0.0345" />
        <axis xyz="0 1 0" />
    </joint>
    <!-- In reality, Jackal has only two motors, one per side. However, it's more
         straightforward for Gazebo to simulate as if there's an actuator per wheel. -->
    <transmission name="rear_left_wheel_trans">
        <type>transmission_interface/SimpleTransmission</type>
        <joint name="rear_left_wheel">
            <hardwareInterface>hardware_interface/VelocityJointInterface</hardwareInterface>
        </joint>
        <actuator name="rear_left_actuator">
            <mechanicalReduction>1</mechanicalReduction>
            <hardwareInterface>hardware_interface/EffortJointInterface</hardwareInterface>
        </actuator>
    </transmission>
    <link name="rear_right_wheel_link">
        <visual>
            <origin rpy="1.5707963267948966 0 0" xyz="0 0 0" />
            <geometry>
                <mesh filename="package://jackal_description/meshes/jackal-wheel.stl" />
            </geometry>
            <material name="black" />
        </visual>
        <collision>
            <origin rpy="1.5707963267948966 0 0" xyz="0 0 0" />
            <geometry>
                <cylinder length="0.04" radius="0.098" />
            </geometry>
        </collision>
        <inertial>
            <origin rpy="0 0 0" xyz="0 0 0" />
            <mass value="0.477" />
            <inertia ixx="0.0013" ixy="0" ixz="0" iyy="0.0024" iyz="0" izz="0.0013" />
        </inertial>
    </link>
    <gazebo reference="rear_right_wheel_link">
        <material>Gazebo/DarkGrey</material>
        <selfCollide>false</selfCollide>
        <mu1 value="0.5" />
        <mu2 value="0.5" />
        <kp value="10000000.0" />
        <kd value="1" />
        <fdir1 value="1 0 0" />
    </gazebo>
    <joint name="rear_right_wheel" type="continuous">
        <parent link="chassis_link" />
        <child link="rear_right_wheel_link" />
        <origin rpy="0 0 0" xyz="-0.131 -0.187795 0.0345" />
        <axis xyz="0 1 0" />
    </joint>
    <!-- In reality, Jackal has only two motors, one per side. However, it's more
         straightforward for Gazebo to simulate as if there's an actuator per wheel. -->
    <transmission name="rear_right_wheel_trans">
        <type>transmission_interface/SimpleTransmission</type>
        <joint name="rear_right_wheel">
            <hardwareInterface>hardware_interface/VelocityJointInterface</hardwareInterface>
        </joint>
        <actuator name="rear_right_actuator">
            <mechanicalReduction>1</mechanicalReduction>
            <hardwareInterface>hardware_interface/EffortJointInterface</hardwareInterface>
        </actuator>
    </transmission>
    <link name="base_link" />
    <joint name="base_link_joint" type="fixed">
        <origin rpy="0 0 0" xyz="0 0 0" />
        <parent link="base_link" />
        <child link="chassis_link" />
    </joint>
    <link name="chassis_link">
        <visual>
            <origin rpy="1.5707963267948966 0 1.5707963267948966" xyz="0 0 -0.0655" />
            <geometry>
                <mesh filename="package://jackal_description/meshes/jackal-base.stl" />
            </geometry>
            <material name="dark_grey" />
        </visual>
        <collision>
            <origin xyz="0 0 0.092" />
            <geometry>
                <box size="0.42 0.31 0.184" />
            </geometry>
        </collision>
        <inertial>
            <!-- Center of mass -->
            <origin rpy="0 0 0" xyz="0.012  0.002 0.067" />
            <mass value="16.523" />
            <!-- Moments of inertia: ( chassis without wheels ) -->
            <inertia ixx="0.3136" ixy="-0.0008" ixz="0.0164" iyy="0.3922" iyz="-0.0009" izz="0.4485" />
        </inertial>
    </link>
    <link name="front_fender_link">
        <visual>
            <geometry>
                <mesh filename="package://jackal_description/meshes/jackal-fender.stl" />
            </geometry>
            <material name="yellow" />
        </visual>
    </link>
    <joint name="front_fender_joint" type="fixed">
        <origin rpy="0 0 0" xyz="0 0 0" />
        <parent link="chassis_link" />
        <child link="front_fender_link" />
    </joint>
    <link name="rear_fender_link">
        <visual>
            <geometry>
                <mesh filename="package://jackal_description/meshes/jackal-fender.stl" />
            </geometry>
            <material name="yellow" />
        </visual>
    </link>
    <joint name="rear_fender_joint" type="fixed">
        <origin rpy="0 0 3.141592653589793" xyz="0 0 0" />
        <parent link="chassis_link" />
        <child link="rear_fender_link" />
    </joint>
    <!-- Default Internal IMU Link -->
    <link name="imu_link">
        <inertial>
            <mass value="0.001" />
            <origin rpy="0 0 0" xyz="0 0 0" />
            <inertia ixx="1e-09" ixy="0.0" ixz="0.0" iyy="1e-09" iyz="0.0" izz="1e-09" />
        </inertial>
    </link>
    <joint name="imu_joint" type="fixed">
        <parent link="chassis_link" />
        <child link="imu_link" />
    </joint>
    <!-- Default NAVSAT Link -->
    <link name="navsat_link">
        <visual>
            <geometry>
                <cylinder length="0.016" radius="0.026" />
            </geometry>
            <origin xyz="0 0 0.008" />
            <material name="black" />
        </visual>
    </link>
    <joint name="navsat_joint" type="fixed">
        <parent link="chassis_link" />
        <child link="navsat_link" />
        <origin xyz="-0.180 0.126 0.1815" />
    </joint>
    <link name="mid_mount" />
    <joint name="mid_mount_joint" type="fixed">
        <parent link="chassis_link" />
        <child link="mid_mount" />
        <origin xyz="0 0 0.184" />
    </joint>
    <link name="rear_mount" />
    <joint name="rear_mount_joint" type="fixed">
        <parent link="mid_mount" />
        <child link="rear_mount" />
        <origin xyz="-0.12 0 0" />
    </joint>
    <link name="front_mount" />
    <joint name="front_mount_joint" type="fixed">
        <parent link="mid_mount" />
        <child link="front_mount" />
        <origin xyz="0.12 0 0" />
    </joint>
    <gazebo>
        <plugin filename="libgazebo_ros_control.so" name="gazebo_ros_control">
            <robotNamespace>/</robotNamespace>
        </plugin>
    </gazebo>
    <gazebo>
        <plugin filename="libhector_gazebo_ros_imu.so" name="imu_controller">
            <robotNamespace>/</robotNamespace>
            <updateRate>50.0</updateRate>
            <bodyName>imu_link</bodyName>
            <topicName>imu/data</topicName>
            <accelDrift>0.005 0.005 0.005</accelDrift>
            <accelGaussianNoise>0.005 0.005 0.005</accelGaussianNoise>
            <rateDrift>0.005 0.005 0.005</rateDrift>
            <rateGaussianNoise>0.005 0.005 0.005</rateGaussianNoise>
            <headingDrift>0.005</headingDrift>
            <headingGaussianNoise>0.005</headingGaussianNoise>
        </plugin>
    </gazebo>
    <gazebo>
        <plugin filename="libhector_gazebo_ros_gps.so" name="gps_controller">
            <updateRate>40</updateRate>
            <robotNamespace>/</robotNamespace>
            <bodyName>navsat_link</bodyName>
            <frameId>base_link</frameId>
            <topicName>/navsat/fix</topicName>
            <velocityTopicName>/navsat/vel</velocityTopicName>
            <referenceLatitude>49.9</referenceLatitude>
            <referenceLongitude>8.9</referenceLongitude>
            <referenceHeading>90</referenceHeading>
            <referenceAltitude>0</referenceAltitude>
            <drift>0.0001 0.0001 0.0001</drift>
        </plugin>
    </gazebo>
    <gazebo reference="base_link">
        <turnGravityOff>false</turnGravityOff>
    </gazebo>
    <gazebo reference="chassis_link">
        <material>Gazebo/DarkGrey</material>
        <turnGravityOff>false</turnGravityOff>
    </gazebo>
    <gazebo reference="imu_link">
        <turnGravityOff>false</turnGravityOff>
    </gazebo>
    <gazebo reference="navsat_link">
        <material>Gazebo/DarkGrey</material>
        <turnGravityOff>false</turnGravityOff>
    </gazebo>
    <gazebo reference="front_fender_link">
        <material>Gazebo/Yellow</material>
        <turnGravityOff>false</turnGravityOff>
    </gazebo>
    <gazebo reference="rear_fender_link">
        <material>Gazebo/Yellow</material>
        <turnGravityOff>false</turnGravityOff>
    </gazebo>
    <!--
    As you add to this URDF, please be aware that both the robot and
    simulation include it. You must retain compatibility with all of
    the following launch files:

    jackal_viz/launch/view_model.launch
    jackal_gazebo/launch/jackal_world.launch
    jackal_base/launch/base.launch
  -->
    <!-- 
    Add Cameras. 
    - JACKAL_FLEA3
    - JACKAL_STEREO_FLEA3
    - JACKAL_BB2
  -->
    <!-- Zed Camera -->
    <link name="zed_camera_center">
        <origin rpy="0 0 0" xyz="0 0 0" />
        <visual>
            <origin rpy="0 0 3.14159" xyz="-0.04 -0.068 -0.05" />
            <geometry>
                <mesh filename="package://utari10_jackal/meshes/utari10_jackal.STL" />
            </geometry>
            <material name="dark_grey" />
        </visual>
        <collision>
            <origin rpy="0 0 3.14159" xyz="-0.04 -0.068 -0.05" />
            <geometry>
                <mesh filename="package://utari10_jackal/meshes/utari10_jackal.STL" />
            </geometry>
        </collision>
        <inertial>
            <mass value="0.1" />
            <origin xyz="0 0 0" rpy="0 0 0" />
            <inertia ixx="0.03" iyy="0.03" izz="0.03" ixy="0.0" ixz="0.0" iyz="0.0" />
        </inertial>
    </link>
    <joint name="zed_camera_joint" type="fixed">
        <parent link="front_mount" />
        <child link="zed_camera_center" />
        <origin rpy="0 0 0" xyz="0.1 0 0.05" />
    </joint>
    <!-- Left Camera -->
    <joint name="zed_left_camera_joint" type="fixed">
        <parent link="zed_camera_center" />
        <child link="zed_left_camera_frame" />
        <origin rpy="0 0 0" xyz="0 -0.068 0" />
    </joint>
    <link name="zed_left_camera_frame" />
    <joint name="zed_left_camera_optical_joint" type="fixed">
        <origin rpy="0 0 0" xyz="0 0 0" />
        <parent link="zed_left_camera_frame" />
        <child link="zed_left_camera_optical_frame" />
    </joint>
    <link name="zed_left_camera_optical_frame" />
    <!-- Right Camera -->
    <joint name="zed_right_camera_joint" type="fixed">
        <parent link="zed_camera_center" />
        <child link="zed_right_camera_frame" />
        <origin rpy="0 0 0" xyz="0 0.068 0" />
    </joint>
    <link name="zed_right_camera_frame" />
    <joint name="zed_right_camera_optical_joint" type="fixed">
        <origin rpy="0 0 0" xyz="0 0 0" />
        <parent link="zed_right_camera_frame" />
        <child link="zed_right_camera_optical_frame" />
    </joint>
    <link name="zed_right_camera_optical_frame" />
    <!-- Kinova Arm -->
    <link name="j2n6s300_mount" />
    <joint name="kinova_mount" type="fixed">
        <parent link="mid_mount" />
        <child link="j2n6s300_mount" />
        <origin rpy="0 0 1.5708" xyz="0 0 0" />
    </joint>
    <joint name="kinova_base_to_mount" type="fixed">
        <parent link="j2n6s300_mount" />
        <child link="j2n6s300_link_base" />
        <origin rpy="0 0 0" xyz="0 0.03 0" />
    </joint>
    <!-- links      		mesh_no
   base           		0
   shoulder       		1
   arm            		2
   forearm        		3
   wrist          		4
   arm_mico       		5
   arm_half1 (7dof)		6
   arm_half2 (7dof)		7
   wrist_spherical_1  8
   wrist_spherical_2  9

   hand 3 finger  		55
   hand_2finger   		56
   finger_proximal		57
   finger_distal      58
-->
    <!-- links      		mesh_no
   base           		0
   shoulder       		1
   arm            		2
   forearm        		3
   wrist          		4
   arm_mico       		5
   arm_half1 (7dof)		6
   arm_half2 (7dof)		7
   wrist_spherical_1  8
   wrist_spherical_2  9

   hand 3 finger  		55
   hand_2finger   		56
   finger_proximal		57
   finger_distal      58
-->
    <!-- ros_control plugin -->
    <gazebo>
        <plugin filename="libgazebo_ros_control.so" name="gazebo_ros_control">
            <robotNamespace>j2n6s300</robotNamespace>
            <robotSimType>gazebo_ros_control/DefaultRobotHWSim</robotSimType>
            <legacyModeNS>true</legacyModeNS>
        </plugin>
    </gazebo>
    <link name="j2n6s300_link_base">
        <visual>
            <geometry>
                <mesh filename="package://kinova_description/meshes/base.dae" />
            </geometry>
            <material name="carbon_fiber">
                <color rgba="0.792156862745098 0.819607843137255 0.933333333333333 1" />
            </material>
        </visual>
        <collision>
            <geometry>
                <mesh filename="package://kinova_description/meshes/base.dae" />
            </geometry>
        </collision>
        <inertial>
            <mass value="0.46784" />
            <origin rpy="0 0 0" xyz="0 0 0.1255" />
            <inertia ixx="0.000951270861568" ixy="0" ixz="0" iyy="0.000951270861568" iyz="0" izz="0.00037427200000000004" />
        </inertial>
    </link>
    <link name="j2n6s300_link_1">
        <visual>
            <geometry>
                <mesh filename="package://kinova_description/meshes/shoulder.dae" />
            </geometry>
            <material name="carbon_fiber">
                <color rgba="0.792156862745098 0.819607843137255 0.933333333333333 1" />
            </material>
        </visual>
        <visual>
            <geometry>
                <mesh filename="package://kinova_description/meshes/ring_big.dae" />
            </geometry>
        </visual>
        <collision>
            <geometry>
                <mesh filename="package://kinova_description/meshes/shoulder.dae" />
            </geometry>
        </collision>
        <inertial>
            <mass value="0.7477" />
            <origin xyz="0 -0.002 -0.0605" rpy="0 0 0" />
            <inertia ixx="0.0015203172520400004" ixy="0" ixz="0" iyy="0.0015203172520400004" iyz="0" izz="0.00059816" />
        </inertial>
    </link>
    <joint name="j2n6s300_joint_1" type="continuous">
        <parent link="j2n6s300_link_base" />
        <child link="j2n6s300_link_1" />
        <axis xyz="0 0 1" />
        <limit effort="40" velocity="0.6283185307179586" />
        <origin rpy="0 3.141592653589793 0" xyz="0 0 0.15675" />
        <dynamics damping="0.0" friction="0.0" />
    </joint>
    <transmission name="j2n6s300_joint_1_trans">
        <type>transmission_interface/SimpleTransmission</type>
        <joint name="j2n6s300_joint_1">
            <hardwareInterface>hardware_interface/EffortJointInterface</hardwareInterface>
        </joint>
        <actuator name="j2n6s300_joint_1_actuator">
            <hardwareInterface>hardware_interface/EffortJointInterface</hardwareInterface>
            <mechanicalReduction>160</mechanicalReduction>
        </actuator>
    </transmission>
    <!--For torque sensing in simulation-->
    <gazebo reference="j2n6s300_joint_1">
        <provideFeedback>true</provideFeedback>
    </gazebo>
    <gazebo>
        <plugin filename="libgazebo_ros_ft_sensor.so" name="ft_sensor">
            <updateRate>30.0</updateRate>
            <topicName>j2n6s300_joint_1_ft_sensor_topic</topicName>
            <jointName>j2n6s300_joint_1</jointName>
        </plugin>
    </gazebo>
    <link name="j2n6s300_link_2">
        <visual>
            <geometry>
                <mesh filename="package://kinova_description/meshes/arm.dae" />
            </geometry>
            <material name="carbon_fiber">
                <color rgba="0.792156862745098 0.819607843137255 0.933333333333333 1" />
            </material>
        </visual>
        <visual>
            <geometry>
                <mesh filename="package://kinova_description/meshes/ring_big.dae" />
            </geometry>
        </visual>
        <collision>
            <geometry>
                <mesh filename="package://kinova_description/meshes/arm.dae" />
            </geometry>
        </collision>
        <inertial>
            <mass value="0.99" />
            <origin xyz="0 -0.2065 -0.01" rpy="0 0 0" />
            <inertia ixx="0.010502207990999999" ixy="0" ixz="0" iyy="0.0007920000000000001" iyz="0" izz="0.010502207990999999" />
        </inertial>
    </link>
    <joint name="j2n6s300_joint_2" type="revolute">
        <parent link="j2n6s300_link_1" />
        <child link="j2n6s300_link_2" />
        <axis xyz="0 0 1" />
        <limit effort="80" lower="0.8203047484373349" upper="5.462880558742252" velocity="0.6283185307179586" />
        <origin rpy="-1.5707963267948966 0 3.141592653589793" xyz="0 0.0016 -0.11875" />
        <dynamics damping="0.0" friction="0.0" />
    </joint>
    <transmission name="j2n6s300_joint_2_trans">
        <type>transmission_interface/SimpleTransmission</type>
        <joint name="j2n6s300_joint_2">
            <hardwareInterface>hardware_interface/EffortJointInterface</hardwareInterface>
        </joint>
        <actuator name="j2n6s300_joint_2_actuator">
            <hardwareInterface>hardware_interface/EffortJointInterface</hardwareInterface>
            <mechanicalReduction>160</mechanicalReduction>
        </actuator>
    </transmission>
    <!--For torque sensing in simulation-->
    <gazebo reference="j2n6s300_joint_2">
        <provideFeedback>true</provideFeedback>
    </gazebo>
    <gazebo>
        <plugin filename="libgazebo_ros_ft_sensor.so" name="ft_sensor">
            <updateRate>30.0</updateRate>
            <topicName>j2n6s300_joint_2_ft_sensor_topic</topicName>
            <jointName>j2n6s300_joint_2</jointName>
        </plugin>
    </gazebo>
    <link name="j2n6s300_link_3">
        <visual>
            <geometry>
                <mesh filename="package://kinova_description/meshes/forearm.dae" />
            </geometry>
            <material name="carbon_fiber">
                <color rgba="0.792156862745098 0.819607843137255 0.933333333333333 1" />
            </material>
        </visual>
        <visual>
            <geometry>
                <mesh filename="package://kinova_description/meshes/ring_big.dae" />
            </geometry>
        </visual>
        <collision>
            <geometry>
                <mesh filename="package://kinova_description/meshes/forearm.dae" />
            </geometry>
        </collision>
        <inertial>
            <mass value="0.6763" />
            <origin xyz="0 0.081 -0.0086" rpy="0 0 0" />
            <inertia ixx="0.0014202243190800001" ixy="0" ixz="0" iyy="0.000304335" iyz="0" izz="0.0014202243190800001" />
        </inertial>
    </link>
    <joint name="j2n6s300_joint_3" type="revolute">
        <parent link="j2n6s300_link_2" />
        <child link="j2n6s300_link_3" />
        <axis xyz="0 0 1" />
        <limit effort="40" lower="0.33161255787892263" upper="5.951572749300664" velocity="0.6283185307179586" />
        <origin rpy="0 3.141592653589793 0" xyz="0 -0.410 0" />
        <dynamics damping="0.0" friction="0.0" />
    </joint>
    <transmission name="j2n6s300_joint_3_trans">
        <type>transmission_interface/SimpleTransmission</type>
        <joint name="j2n6s300_joint_3">
            <hardwareInterface>hardware_interface/EffortJointInterface</hardwareInterface>
        </joint>
        <actuator name="j2n6s300_joint_3_actuator">
            <hardwareInterface>hardware_interface/EffortJointInterface</hardwareInterface>
            <mechanicalReduction>160</mechanicalReduction>
        </actuator>
    </transmission>
    <!--For torque sensing in simulation-->
    <gazebo reference="j2n6s300_joint_3">
        <provideFeedback>true</provideFeedback>
    </gazebo>
    <gazebo>
        <plugin filename="libgazebo_ros_ft_sensor.so" name="ft_sensor">
            <updateRate>30.0</updateRate>
            <topicName>j2n6s300_joint_3_ft_sensor_topic</topicName>
            <jointName>j2n6s300_joint_3</jointName>
        </plugin>
    </gazebo>
    <link name="j2n6s300_link_4">
        <visual>
            <geometry>
                <mesh filename="package://kinova_description/meshes/wrist.dae" />
            </geometry>
            <material name="carbon_fiber">
                <color rgba="0.792156862745098 0.819607843137255 0.933333333333333 1" />
            </material>
        </visual>
        <visual>
            <geometry>
                <mesh filename="package://kinova_description/meshes/ring_small.dae" />
            </geometry>
        </visual>
        <collision>
            <geometry>
                <mesh filename="package://kinova_description/meshes/wrist.dae" />
            </geometry>
        </collision>
        <inertial>
            <mass value="0.426367" />
            <origin xyz="0 -0.037 -0.0642" rpy="0 0 0" />
            <inertia ixx="7.734969059999999e-05" ixy="0" ixz="0" iyy="7.734969059999999e-05" iyz="0" izz="0.0001428" />
        </inertial>
    </link>
    <joint name="j2n6s300_joint_4" type="continuous">
        <parent link="j2n6s300_link_3" />
        <child link="j2n6s300_link_4" />
        <axis xyz="0 0 1" />
        <limit effort="20" velocity="0.8377580409572781" />
        <origin rpy="-1.5707963267948966 0 3.141592653589793" xyz="0 0.2073 -0.0114" />
        <dynamics damping="0.0" friction="0.0" />
    </joint>
    <transmission name="j2n6s300_joint_4_trans">
        <type>transmission_interface/SimpleTransmission</type>
        <joint name="j2n6s300_joint_4">
            <hardwareInterface>hardware_interface/EffortJointInterface</hardwareInterface>
        </joint>
        <actuator name="j2n6s300_joint_4_actuator">
            <hardwareInterface>hardware_interface/EffortJointInterface</hardwareInterface>
            <mechanicalReduction>160</mechanicalReduction>
        </actuator>
    </transmission>
    <!--For torque sensing in simulation-->
    <gazebo reference="j2n6s300_joint_4">
        <provideFeedback>true</provideFeedback>
    </gazebo>
    <gazebo>
        <plugin filename="libgazebo_ros_ft_sensor.so" name="ft_sensor">
            <updateRate>30.0</updateRate>
            <topicName>j2n6s300_joint_4_ft_sensor_topic</topicName>
            <jointName>j2n6s300_joint_4</jointName>
        </plugin>
    </gazebo>
    <link name="j2n6s300_link_5">
        <visual>
            <geometry>
                <mesh filename="package://kinova_description/meshes/wrist.dae" />
            </geometry>
            <material name="carbon_fiber">
                <color rgba="0.792156862745098 0.819607843137255 0.933333333333333 1" />
            </material>
        </visual>
        <visual>
            <geometry>
                <mesh filename="package://kinova_description/meshes/ring_small.dae" />
            </geometry>
        </visual>
        <collision>
            <geometry>
                <mesh filename="package://kinova_description/meshes/wrist.dae" />
            </geometry>
        </collision>
        <inertial>
            <mass value="0.426367" />
            <origin xyz="0 -0.037 -0.0642" rpy="0 0 0" />
            <inertia ixx="7.734969059999999e-05" ixy="0" ixz="0" iyy="7.734969059999999e-05" iyz="0" izz="0.0001428" />
        </inertial>
    </link>
    <joint name="j2n6s300_joint_5" type="continuous">
        <parent link="j2n6s300_link_4" />
        <child link="j2n6s300_link_5" />
        <axis xyz="0 0 1" />
        <limit effort="20" velocity="0.8377580409572781" />
        <origin rpy="1.0471975511965976 0 3.141592653589793" xyz="0 -0.03703 -0.06414" />
        <dynamics damping="0.0" friction="0.0" />
    </joint>
    <transmission name="j2n6s300_joint_5_trans">
        <type>transmission_interface/SimpleTransmission</type>
        <joint name="j2n6s300_joint_5">
            <hardwareInterface>hardware_interface/EffortJointInterface</hardwareInterface>
        </joint>
        <actuator name="j2n6s300_joint_5_actuator">
            <hardwareInterface>hardware_interface/EffortJointInterface</hardwareInterface>
            <mechanicalReduction>160</mechanicalReduction>
        </actuator>
    </transmission>
    <!--For torque sensing in simulation-->
    <gazebo reference="j2n6s300_joint_5">
        <provideFeedback>true</provideFeedback>
    </gazebo>
    <gazebo>
        <plugin filename="libgazebo_ros_ft_sensor.so" name="ft_sensor">
            <updateRate>30.0</updateRate>
            <topicName>j2n6s300_joint_5_ft_sensor_topic</topicName>
            <jointName>j2n6s300_joint_5</jointName>
        </plugin>
    </gazebo>
    <link name="j2n6s300_link_6">
        <visual>
            <geometry>
                <mesh filename="package://kinova_description/meshes/hand_3finger.dae" />
            </geometry>
            <material name="carbon_fiber">
                <color rgba="0.792156862745098 0.819607843137255 0.933333333333333 1" />
            </material>
        </visual>
        <visual>
            <geometry>
                <mesh filename="package://kinova_description/meshes/ring_small.dae" />
            </geometry>
        </visual>
        <collision>
            <geometry>
                <mesh filename="package://kinova_description/meshes/hand_3finger.dae" />
            </geometry>
        </collision>
        <inertial>
            <mass value="0.99" />
            <origin xyz="0 0 -0.06" rpy="0 0 0" />
            <inertia ixx="0.00034532361869999995" ixy="0" ixz="0" iyy="0.00034532361869999995" iyz="0" izz="0.0005815999999999999" />
        </inertial>
    </link>
    <joint name="j2n6s300_joint_6" type="continuous">
        <parent link="j2n6s300_link_5" />
        <child link="j2n6s300_link_6" />
        <axis xyz="0 0 1" />
        <limit effort="20" velocity="0.8377580409572781" />
        <origin rpy="1.0471975511965976 0 3.141592653589793" xyz="0 -0.03703 -0.06414" />
        <dynamics damping="0.0" friction="0.0" />
    </joint>
    <transmission name="j2n6s300_joint_6_trans">
        <type>transmission_interface/SimpleTransmission</type>
        <joint name="j2n6s300_joint_6">
            <hardwareInterface>hardware_interface/EffortJointInterface</hardwareInterface>
        </joint>
        <actuator name="j2n6s300_joint_6_actuator">
            <hardwareInterface>hardware_interface/EffortJointInterface</hardwareInterface>
            <mechanicalReduction>160</mechanicalReduction>
        </actuator>
    </transmission>
    <!--For torque sensing in simulation-->
    <gazebo reference="j2n6s300_joint_6">
        <provideFeedback>true</provideFeedback>
    </gazebo>
    <gazebo>
        <plugin filename="libgazebo_ros_ft_sensor.so" name="ft_sensor">
            <updateRate>30.0</updateRate>
            <topicName>j2n6s300_joint_6_ft_sensor_topic</topicName>
            <jointName>j2n6s300_joint_6</jointName>
        </plugin>
    </gazebo>
    <link name="j2n6s300_end_effector" />
    <joint name="j2n6s300_joint_end_effector" type="fixed">
        <parent link="j2n6s300_link_6" />
        <child link="j2n6s300_end_effector" />
        <axis xyz="0 0 0" />
        <origin rpy="3.141592653589793 0 1.5707963267948966" xyz="0 0 -0.1600" />
    </joint>
    <link name="j2n6s300_link_finger_1">
        <visual>
            <geometry>
                <mesh filename="package://kinova_description/meshes/finger_proximal.dae" />
            </geometry>
            <material name="carbon_fiber">
                <color rgba="0.792156862745098 0.819607843137255 0.933333333333333 1" />
            </material>
        </visual>
        <collision>
            <geometry>
                <mesh filename="package://kinova_description/meshes/finger_proximal.dae" />
            </geometry>
        </collision>
        <inertial>
            <mass value="0.01" />
            <origin xyz="0.022 0 0" rpy="0 0 0" />
            <inertia ixx="7.8999684e-07" ixy="0" ixz="0" iyy="7.8999684e-07" iyz="0" izz="8e-08" />
        </inertial>
    </link>
    <joint name="j2n6s300_joint_finger_1" type="revolute">
        <parent link="j2n6s300_link_6" />
        <child link="j2n6s300_link_finger_1" />
        <axis xyz="0 0 1" />
        <origin rpy="-1.7047873384941834 0.6476144647144773 1.67317415161155" xyz="0.00279 0.03126 -0.11467" />
        <limit effort="2" lower="0" upper="1.51" velocity="1" />
    </joint>
    <transmission name="j2n6s300_joint_finger_1_trans">
        <type>transmission_interface/SimpleTransmission</type>
        <joint name="j2n6s300_joint_finger_1">
            <hardwareInterface>hardware_interface/EffortJointInterface</hardwareInterface>
        </joint>
        <actuator name="j2n6s300_joint_finger_1_actuator">
            <hardwareInterface>hardware_interface/EffortJointInterface</hardwareInterface>
            <mechanicalReduction>1</mechanicalReduction>
        </actuator>
    </transmission>
    <link name="j2n6s300_link_finger_tip_1">
        <visual>
            <geometry>
                <mesh filename="package://kinova_description/meshes/finger_distal.dae" />
            </geometry>
            <material name="carbon_fiber">
                <color rgba="0.792156862745098 0.819607843137255 0.933333333333333 1" />
            </material>
        </visual>
        <collision>
            <geometry>
                <mesh filename="package://kinova_description/meshes/finger_distal.dae" />
            </geometry>
        </collision>
        <inertial>
            <mass value="0.01" />
            <origin xyz="0.022 0 0" rpy="0 0 0" />
            <inertia ixx="7.8999684e-07" ixy="0" ixz="0" iyy="7.8999684e-07" iyz="0" izz="8e-08" />
        </inertial>
    </link>
    <joint name="j2n6s300_joint_finger_tip_1" type="revolute">
        <parent link="j2n6s300_link_finger_1" />
        <child link="j2n6s300_link_finger_tip_1" />
        <axis xyz="0 0 1" />
        <origin rpy="0 0 0" xyz="0.044 -0.003 0" />
        <limit effort="2" lower="0" upper="2" velocity="1" />
    </joint>
    <transmission name="j2n6s300_joint_finger_tip_1_trans">
        <type>transmission_interface/SimpleTransmission</type>
        <joint name="j2n6s300_joint_finger_tip_1">
            <hardwareInterface>hardware_interface/EffortJointInterface</hardwareInterface>
        </joint>
        <actuator name="j2n6s300_joint_finger_tip_1_actuator">
            <hardwareInterface>hardware_interface/EffortJointInterface</hardwareInterface>
            <mechanicalReduction>1</mechanicalReduction>
        </actuator>
    </transmission>
    <link name="j2n6s300_link_finger_2">
        <visual>
            <geometry>
                <mesh filename="package://kinova_description/meshes/finger_proximal.dae" />
            </geometry>
            <material name="carbon_fiber">
                <color rgba="0.792156862745098 0.819607843137255 0.933333333333333 1" />
            </material>
        </visual>
        <collision>
            <geometry>
                <mesh filename="package://kinova_description/meshes/finger_proximal.dae" />
            </geometry>
        </collision>
        <inertial>
            <mass value="0.01" />
            <origin xyz="0.022 0 0" rpy="0 0 0" />
            <inertia ixx="7.8999684e-07" ixy="0" ixz="0" iyy="7.8999684e-07" iyz="0" izz="8e-08" />
        </inertial>
    </link>
    <joint name="j2n6s300_joint_finger_2" type="revolute">
        <parent link="j2n6s300_link_6" />
        <child link="j2n6s300_link_finger_2" />
        <axis xyz="0 0 1" />
        <origin rpy="-1.570796327 .649262481663582 -1.38614049188413" xyz="0.02226 -0.02707 -0.11482" />
        <limit effort="2" lower="0" upper="1.51" velocity="1" />
    </joint>
    <transmission name="j2n6s300_joint_finger_2_trans">
        <type>transmission_interface/SimpleTransmission</type>
        <joint name="j2n6s300_joint_finger_2">
            <hardwareInterface>hardware_interface/EffortJointInterface</hardwareInterface>
        </joint>
        <actuator name="j2n6s300_joint_finger_2_actuator">
            <hardwareInterface>hardware_interface/EffortJointInterface</hardwareInterface>
            <mechanicalReduction>1</mechanicalReduction>
        </actuator>
    </transmission>
    <link name="j2n6s300_link_finger_tip_2">
        <visual>
            <geometry>
                <mesh filename="package://kinova_description/meshes/finger_distal.dae" />
            </geometry>
            <material name="carbon_fiber">
                <color rgba="0.792156862745098 0.819607843137255 0.933333333333333 1" />
            </material>
        </visual>
        <collision>
            <geometry>
                <mesh filename="package://kinova_description/meshes/finger_distal.dae" />
            </geometry>
        </collision>
        <inertial>
            <mass value="0.01" />
            <origin xyz="0.022 0 0" rpy="0 0 0" />
            <inertia ixx="7.8999684e-07" ixy="0" ixz="0" iyy="7.8999684e-07" iyz="0" izz="8e-08" />
        </inertial>
    </link>
    <joint name="j2n6s300_joint_finger_tip_2" type="revolute">
        <parent link="j2n6s300_link_finger_2" />
        <child link="j2n6s300_link_finger_tip_2" />
        <axis xyz="0 0 1" />
        <origin rpy="0 0 0" xyz="0.044 -0.003 0" />
        <limit effort="2" lower="0" upper="2" velocity="1" />
    </joint>
    <transmission name="j2n6s300_joint_finger_tip_2_trans">
        <type>transmission_interface/SimpleTransmission</type>
        <joint name="j2n6s300_joint_finger_tip_2">
            <hardwareInterface>hardware_interface/EffortJointInterface</hardwareInterface>
        </joint>
        <actuator name="j2n6s300_joint_finger_tip_2_actuator">
            <hardwareInterface>hardware_interface/EffortJointInterface</hardwareInterface>
            <mechanicalReduction>1</mechanicalReduction>
        </actuator>
    </transmission>
    <link name="j2n6s300_link_finger_3">
        <visual>
            <geometry>
                <mesh filename="package://kinova_description/meshes/finger_proximal.dae" />
            </geometry>
            <material name="carbon_fiber">
                <color rgba="0.792156862745098 0.819607843137255 0.933333333333333 1" />
            </material>
        </visual>
        <collision>
            <geometry>
                <mesh filename="package://kinova_description/meshes/finger_proximal.dae" />
            </geometry>
        </collision>
        <inertial>
            <mass value="0.01" />
            <origin xyz="0.022 0 0" rpy="0 0 0" />
            <inertia ixx="7.8999684e-07" ixy="0" ixz="0" iyy="7.8999684e-07" iyz="0" izz="8e-08" />
        </inertial>
    </link>
    <joint name="j2n6s300_joint_finger_3" type="revolute">
        <parent link="j2n6s300_link_6" />
        <child link="j2n6s300_link_finger_3" />
        <axis xyz="0 0 1" />
        <origin rpy="-1.570796327 .649262481663582 -1.75545216211587" xyz="-0.02226 -0.02707 -0.11482" />
        <limit effort="2" lower="0" upper="1.51" velocity="1" />
    </joint>
    <transmission name="j2n6s300_joint_finger_3_trans">
        <type>transmission_interface/SimpleTransmission</type>
        <joint name="j2n6s300_joint_finger_3">
            <hardwareInterface>hardware_interface/EffortJointInterface</hardwareInterface>
        </joint>
        <actuator name="j2n6s300_joint_finger_3_actuator">
            <hardwareInterface>hardware_interface/EffortJointInterface</hardwareInterface>
            <mechanicalReduction>1</mechanicalReduction>
        </actuator>
    </transmission>
    <link name="j2n6s300_link_finger_tip_3">
        <visual>
            <geometry>
                <mesh filename="package://kinova_description/meshes/finger_distal.dae" />
            </geometry>
            <material name="carbon_fiber">
                <color rgba="0.792156862745098 0.819607843137255 0.933333333333333 1" />
            </material>
        </visual>
        <collision>
            <geometry>
                <mesh filename="package://kinova_description/meshes/finger_distal.dae" />
            </geometry>
        </collision>
        <inertial>
            <mass value="0.01" />
            <origin xyz="0.022 0 0" rpy="0 0 0" />
            <inertia ixx="7.8999684e-07" ixy="0" ixz="0" iyy="7.8999684e-07" iyz="0" izz="8e-08" />
        </inertial>
    </link>
    <joint name="j2n6s300_joint_finger_tip_3" type="revolute">
        <parent link="j2n6s300_link_finger_3" />
        <child link="j2n6s300_link_finger_tip_3" />
        <axis xyz="0 0 1" />
        <origin rpy="0 0 0" xyz="0.044 -0.003 0" />
        <limit effort="2" lower="0" upper="2" velocity="1" />
    </joint>
    <transmission name="j2n6s300_joint_finger_tip_3_trans">
        <type>transmission_interface/SimpleTransmission</type>
        <joint name="j2n6s300_joint_finger_tip_3">
            <hardwareInterface>hardware_interface/EffortJointInterface</hardwareInterface>
        </joint>
        <actuator name="j2n6s300_joint_finger_tip_3_actuator">
            <hardwareInterface>hardware_interface/EffortJointInterface</hardwareInterface>
            <mechanicalReduction>1</mechanicalReduction>
        </actuator>
    </transmission>
    <!-- This file is a placeholder which is included by default from
       jackal.urdf.xacro. If a robot is being customized and requires
       additional URDF, set the JACKAL_URDF_EXTRAS environment variable
       to the full path of the file you would like included. -->
</robot>

